Traceback (most recent call last):
  File "C:\Users\Matias Villalba\AppData\Local\Programs\Python\Python312\Lib\site-packages\jupyter_cache\executors\utils.py", line 58, in single_nb_execution
    executenb(
  File "C:\Users\Matias Villalba\AppData\Local\Programs\Python\Python312\Lib\site-packages\nbclient\client.py", line 1314, in execute
    return NotebookClient(nb=nb, resources=resources, km=km, **kwargs).execute()
           ^^^^^^^^^^^^^^^^^^^^^^^^^^^^^^^^^^^^^^^^^^^^^^^^^^^^^^^^^^^^^^^^^^^^^
  File "C:\Users\Matias Villalba\AppData\Local\Programs\Python\Python312\Lib\site-packages\jupyter_core\utils\__init__.py", line 165, in wrapped
    return loop.run_until_complete(inner)
           ^^^^^^^^^^^^^^^^^^^^^^^^^^^^^^
  File "C:\Users\Matias Villalba\AppData\Local\Programs\Python\Python312\Lib\asyncio\base_events.py", line 685, in run_until_complete
    return future.result()
           ^^^^^^^^^^^^^^^
  File "C:\Users\Matias Villalba\AppData\Local\Programs\Python\Python312\Lib\site-packages\nbclient\client.py", line 709, in async_execute
    await self.async_execute_cell(
  File "C:\Users\Matias Villalba\AppData\Local\Programs\Python\Python312\Lib\site-packages\nbclient\client.py", line 1062, in async_execute_cell
    await self._check_raise_for_error(cell, cell_index, exec_reply)
  File "C:\Users\Matias Villalba\AppData\Local\Programs\Python\Python312\Lib\site-packages\nbclient\client.py", line 918, in _check_raise_for_error
    raise CellExecutionError.from_cell_and_msg(cell, exec_reply_content)
nbclient.exceptions.CellExecutionError: An error occurred while executing the following cell:
------------------
rm(list=ls())
DML <- as.data.frame(read.table("../../../data/processed_esti.csv", header=T ,sep=","))
#DML <- as.data.frame(read.table("C:/Users/Erzo/Documents/GitHub/CausalAI-Course/data/processed_esti.csv", header=T ,sep=","))

set.seed(1234)
training <- sample(nrow(DML), nrow(DML)*(3/4), replace=FALSE)
data_train <- DML[training,]
data_test <- DML[-training,]
Y_test <- data_test$y

y = as.matrix(data_train[,1])         # outcome: growth rate
d = as.matrix(data_train[,2])         # treatment: initial wealth
x = as.matrix(data_train[,-c(1,2)]) # controls: country characteristics
------------------

----- stderr -----
Warning message in file(file, "rt"):
"cannot open file '../../../data/processed_esti.csv': No such file or directory"
------------------

Error in file(file, "rt"): cannot open the connection
Traceback:

1. as.data.frame(read.table("../../../data/processed_esti.csv", 
 .     header = T, sep = ","))
2. read.table("../../../data/processed_esti.csv", header = T, sep = ",")
3. file(file, "rt")

